<?xml version="0.0" ?>
<robot name="">
	<link name="torso">
		<inertial>
			<origin rpy="0.00000 -0.00000 0.00000" xyz="0.00000 0.00000 0.00000"/>
			<mass value="65.44985"/>
			<inertia ixx="1.63625" ixy="0" ixz="0" iyy="1.63625" iyz="0" izz="1.63625"/>
		</inertial>
		<visual>
			<origin rpy="0.00000 -0.00000 0.00000" xyz="0.00000 0.00000 0.00000"/>
			<geometry>
				<sphere radius="0.25000"/>
			</geometry>
			<material name="mat_-1_0">
				<color rgba="0.23438 0.72656 0.32812 1.00000" />
			</material>
		</visual>
		<collision>
			<origin rpy="0.00000 -0.00000 0.00000" xyz="0.00000 0.00000 0.00000"/>
			<geometry>
				<sphere radius="0.25000"/>
			</geometry>
		</collision>
	</link>
	<link name="front_left_leg">
		<inertial>
			<origin rpy="0.00000 -0.00000 0.00000" xyz="0.10000 0.10000 0.00000"/>
			<mass value="7.83155"/>
			<inertia ixx="0.16394" ixy="0" ixz="0" iyy="0.16394" iyz="0" izz="0.25270"/>
		</inertial>
		<visual>
			<origin rpy="0.00000 -0.00000 0.00000" xyz="0.00000 0.00000 0.00000"/>
			<geometry>
				<capsule length="0.28284" radius="0.08000"/>
			</geometry>
			<material name="mat_0_0">
				<color rgba="0.95312 0.75781 0.05078 1.00000" />
			</material>
		</visual>
	</link>
	<link name="link0_3">
		<inertial>
			<origin rpy="0.00000 -0.00000 0.00000" xyz="0.00000 0.00000 0.00000"/>
			<mass value="0.00000"/>
			<inertia ixx="0.00000" ixy="0" ixz="0" iyy="0.00000" iyz="0" izz="0.00000"/>
		</inertial>
	</link>
	<link name="aux_1">
		<inertial>
			<origin rpy="0.00000 -0.00000 0.00000" xyz="0.10000 0.10000 0.00000"/>
			<mass value="7.83155"/>
			<inertia ixx="0.16394" ixy="0" ixz="0" iyy="0.16394" iyz="0" izz="0.25270"/>
		</inertial>
		<visual>
			<origin rpy="0.00000 -0.00000 0.00000" xyz="0.00000 0.00000 0.00000"/>
			<geometry>
				<capsule length="0.28284" radius="0.08000"/>
			</geometry>
			<material name="mat_2_0">
				<color rgba="0.85547 0.19531 0.21094 1.00000" />
			</material>
		</visual>
	</link>
	<link name="link0_5">
		<inertial>
			<origin rpy="0.00000 -0.00000 0.00000" xyz="0.00000 0.00000 0.00000"/>
			<mass value="0.00000"/>
			<inertia ixx="0.00000" ixy="0" ixz="0" iyy="0.00000" iyz="0" izz="0.00000"/>
		</inertial>
	</link>
	<link name="front_left_foot">
		<inertial>
			<origin rpy="0.00000 -0.00000 0.00000" xyz="0.20000 0.20000 0.00000"/>
			<mass value="13.51844"/>
			<inertia ixx="0.52632" ixy="0" ixz="0" iyy="0.52632" iyz="0" izz="0.92286"/>
		</inertial>
		<visual>
			<origin rpy="0.00000 -0.00000 0.00000" xyz="0.00000 0.00000 0.00000"/>
			<geometry>
				<capsule length="0.56569" radius="0.08000"/>
			</geometry>
			<material name="mat_4_0">
				<color rgba="0.23438 0.72656 0.32812 1.00000" />
			</material>
		</visual>
	</link>
	<link name="front_right_leg">
		<inertial>
			<origin rpy="0.00000 -0.00000 0.00000" xyz="-0.10000 0.10000 0.00000"/>
			<mass value="7.83155"/>
			<inertia ixx="0.16394" ixy="0" ixz="0" iyy="0.16394" iyz="0" izz="0.25270"/>
		</inertial>
		<visual>
			<origin rpy="0.00000 -0.00000 0.00000" xyz="0.00000 0.00000 0.00000"/>
			<geometry>
				<capsule length="0.28284" radius="0.08000"/>
			</geometry>
			<material name="mat_5_0">
				<color rgba="0.85547 0.19531 0.21094 1.00000" />
			</material>
		</visual>
	</link>
	<link name="link0_8">
		<inertial>
			<origin rpy="0.00000 -0.00000 0.00000" xyz="0.00000 0.00000 0.00000"/>
			<mass value="0.00000"/>
			<inertia ixx="0.00000" ixy="0" ixz="0" iyy="0.00000" iyz="0" izz="0.00000"/>
		</inertial>
	</link>
	<link name="aux_2">
		<inertial>
			<origin rpy="0.00000 -0.00000 0.00000" xyz="-0.10000 0.10000 0.00000"/>
			<mass value="7.83155"/>
			<inertia ixx="0.16394" ixy="0" ixz="0" iyy="0.16394" iyz="0" izz="0.25270"/>
		</inertial>
		<visual>
			<origin rpy="0.00000 -0.00000 0.00000" xyz="0.00000 0.00000 0.00000"/>
			<geometry>
				<capsule length="0.28284" radius="0.08000"/>
			</geometry>
			<material name="mat_7_0">
				<color rgba="0.28125 0.51953 0.92578 1.00000" />
			</material>
		</visual>
	</link>
	<link name="link0_10">
		<inertial>
			<origin rpy="0.00000 -0.00000 0.00000" xyz="0.00000 0.00000 0.00000"/>
			<mass value="0.00000"/>
			<inertia ixx="0.00000" ixy="0" ixz="0" iyy="0.00000" iyz="0" izz="0.00000"/>
		</inertial>
	</link>
	<link name="front_right_foot">
		<inertial>
			<origin rpy="0.00000 -0.00000 0.00000" xyz="-0.20000 0.20000 0.00000"/>
			<mass value="13.51844"/>
			<inertia ixx="0.52632" ixy="0" ixz="0" iyy="0.52632" iyz="0" izz="0.92286"/>
		</inertial>
		<visual>
			<origin rpy="0.00000 -0.00000 0.00000" xyz="0.00000 0.00000 0.00000"/>
			<geometry>
				<capsule length="0.56569" radius="0.08000"/>
			</geometry>
			<material name="mat_9_0">
				<color rgba="0.95312 0.75781 0.05078 1.00000" />
			</material>
		</visual>
	</link>
	<link name="left_back_leg">
		<inertial>
			<origin rpy="0.00000 -0.00000 0.00000" xyz="-0.10000 -0.10000 0.00000"/>
			<mass value="7.83155"/>
			<inertia ixx="0.16394" ixy="0" ixz="0" iyy="0.16394" iyz="0" izz="0.25270"/>
		</inertial>
		<visual>
			<origin rpy="0.00000 -0.00000 0.00000" xyz="0.00000 0.00000 0.00000"/>
			<geometry>
				<capsule length="0.28284" radius="0.08000"/>
			</geometry>
			<material name="mat_10_0">
				<color rgba="0.28125 0.51953 0.92578 1.00000" />
			</material>
		</visual>
	</link>
	<link name="link0_13">
		<inertial>
			<origin rpy="0.00000 -0.00000 0.00000" xyz="0.00000 0.00000 0.00000"/>
			<mass value="0.00000"/>
			<inertia ixx="0.00000" ixy="0" ixz="0" iyy="0.00000" iyz="0" izz="0.00000"/>
		</inertial>
	</link>
	<link name="aux_3">
		<inertial>
			<origin rpy="0.00000 -0.00000 0.00000" xyz="-0.10000 -0.10000 0.00000"/>
			<mass value="7.83155"/>
			<inertia ixx="0.16394" ixy="0" ixz="0" iyy="0.16394" iyz="0" izz="0.25270"/>
		</inertial>
		<visual>
			<origin rpy="0.00000 -0.00000 0.00000" xyz="0.00000 0.00000 0.00000"/>
			<geometry>
				<capsule length="0.28284" radius="0.08000"/>
			</geometry>
			<material name="mat_12_0">
				<color rgba="0.23438 0.72656 0.32812 1.00000" />
			</material>
		</visual>
	</link>
	<link name="link0_15">
		<inertial>
			<origin rpy="0.00000 -0.00000 0.00000" xyz="0.00000 0.00000 0.00000"/>
			<mass value="0.00000"/>
			<inertia ixx="0.00000" ixy="0" ixz="0" iyy="0.00000" iyz="0" izz="0.00000"/>
		</inertial>
	</link>
	<link name="left_back_foot">
		<inertial>
			<origin rpy="0.00000 -0.00000 0.00000" xyz="-0.20000 -0.20000 0.00000"/>
			<mass value="13.51844"/>
			<inertia ixx="0.52632" ixy="0" ixz="0" iyy="0.52632" iyz="0" izz="0.92286"/>
		</inertial>
		<visual>
			<origin rpy="0.00000 -0.00000 0.00000" xyz="0.00000 0.00000 0.00000"/>
			<geometry>
				<capsule length="0.56569" radius="0.08000"/>
			</geometry>
			<material name="mat_14_0">
				<color rgba="0.85547 0.19531 0.21094 1.00000" />
			</material>
		</visual>
	</link>
	<link name="right_back_leg">
		<inertial>
			<origin rpy="0.00000 -0.00000 0.00000" xyz="0.10000 -0.10000 0.00000"/>
			<mass value="7.83155"/>
			<inertia ixx="0.16394" ixy="0" ixz="0" iyy="0.16394" iyz="0" izz="0.25270"/>
		</inertial>
		<visual>
			<origin rpy="0.00000 -0.00000 0.00000" xyz="0.00000 0.00000 0.00000"/>
			<geometry>
				<capsule length="0.28284" radius="0.08000"/>
			</geometry>
			<material name="mat_15_0">
				<color rgba="0.23438 0.72656 0.32812 1.00000" />
			</material>
		</visual>
	</link>
	<link name="link0_18">
		<inertial>
			<origin rpy="0.00000 -0.00000 0.00000" xyz="0.00000 0.00000 0.00000"/>
			<mass value="0.00000"/>
			<inertia ixx="0.00000" ixy="0" ixz="0" iyy="0.00000" iyz="0" izz="0.00000"/>
		</inertial>
	</link>
	<link name="aux_4">
		<inertial>
			<origin rpy="0.00000 -0.00000 0.00000" xyz="0.10000 -0.10000 0.00000"/>
			<mass value="7.83155"/>
			<inertia ixx="0.16394" ixy="0" ixz="0" iyy="0.16394" iyz="0" izz="0.25270"/>
		</inertial>
		<visual>
			<origin rpy="0.00000 -0.00000 0.00000" xyz="0.00000 0.00000 0.00000"/>
			<geometry>
				<capsule length="0.28284" radius="0.08000"/>
			</geometry>
			<material name="mat_17_0">
				<color rgba="0.95312 0.75781 0.05078 1.00000" />
			</material>
		</visual>
	</link>
	<link name="link0_20">
		<inertial>
			<origin rpy="0.00000 -0.00000 0.00000" xyz="0.00000 0.00000 0.00000"/>
			<mass value="0.00000"/>
			<inertia ixx="0.00000" ixy="0" ixz="0" iyy="0.00000" iyz="0" izz="0.00000"/>
		</inertial>
	</link>
	<link name="right_back_foot">
		<inertial>
			<origin rpy="0.00000 -0.00000 0.00000" xyz="0.20000 -0.20000 0.00000"/>
			<mass value="13.51844"/>
			<inertia ixx="0.52632" ixy="0" ixz="0" iyy="0.52632" iyz="0" izz="0.92286"/>
		</inertial>
		<visual>
			<origin rpy="0.00000 -0.00000 0.00000" xyz="0.00000 0.00000 0.00000"/>
			<geometry>
				<capsule length="0.56569" radius="0.08000"/>
			</geometry>
			<material name="mat_19_0">
				<color rgba="0.28125 0.51953 0.92578 1.00000" />
			</material>
		</visual>
	</link>
	<joint name="jointfix_2_0" type="fixed">
		<parent link="torso"/>
		<child link="front_left_leg"/>
		<dynamics damping="1.0" friction="0.0001"/>
		<origin rpy="0.00000 -0.00000 0.00000" xyz="0.00000 0.00000 0.00000"/>
		<axis xyz="0.00000 0.00000 0.00000"/>
	</joint>
	<joint name="hip_1" type="continuous">
		<parent link="front_left_leg"/>
		<child link="link0_3"/>
		<dynamics damping="1.0" friction="0.0001"/>
		<origin rpy="0.00000 -0.00000 0.00000" xyz="0.20000 0.20000 0.00000"/>
		<axis xyz="0.00000 0.00000 1.00000"/>
	</joint>
	<joint name="jointfix_1_3" type="fixed">
		<parent link="link0_3"/>
		<child link="aux_1"/>
		<dynamics damping="1.0" friction="0.0001"/>
		<origin rpy="0.00000 -0.00000 0.00000" xyz="0.00000 0.00000 0.00000"/>
		<axis xyz="0.00000 0.00000 0.00000"/>
	</joint>
	<joint name="ankle_1" type="continuous">
		<parent link="aux_1"/>
		<child link="link0_5"/>
		<dynamics damping="1.0" friction="0.0001"/>
		<origin rpy="0.00000 -0.00000 0.00000" xyz="0.20000 0.20000 0.00000"/>
		<axis xyz="-1.00000 1.00000 0.00000"/>
	</joint>
	<joint name="jointfix_0_5" type="fixed">
		<parent link="link0_5"/>
		<child link="front_left_foot"/>
		<dynamics damping="1.0" friction="0.0001"/>
		<origin rpy="0.00000 -0.00000 0.00000" xyz="0.00000 0.00000 0.00000"/>
		<axis xyz="0.00000 0.00000 0.00000"/>
	</joint>
	<joint name="jointfix_5_0" type="fixed">
		<parent link="torso"/>
		<child link="front_right_leg"/>
		<dynamics damping="1.0" friction="0.0001"/>
		<origin rpy="0.00000 -0.00000 0.00000" xyz="0.00000 0.00000 0.00000"/>
		<axis xyz="0.00000 0.00000 0.00000"/>
	</joint>
	<joint name="hip_2" type="continuous">
		<parent link="front_right_leg"/>
		<child link="link0_8"/>
		<dynamics damping="1.0" friction="0.0001"/>
		<origin rpy="0.00000 -0.00000 0.00000" xyz="-0.20000 0.20000 0.00000"/>
		<axis xyz="0.00000 0.00000 1.00000"/>
	</joint>
	<joint name="jointfix_4_8" type="fixed">
		<parent link="link0_8"/>
		<child link="aux_2"/>
		<dynamics damping="1.0" friction="0.0001"/>
		<origin rpy="0.00000 -0.00000 0.00000" xyz="0.00000 0.00000 0.00000"/>
		<axis xyz="0.00000 0.00000 0.00000"/>
	</joint>
	<joint name="ankle_2" type="continuous">
		<parent link="aux_2"/>
		<child link="link0_10"/>
		<dynamics damping="1.0" friction="0.0001"/>
		<origin rpy="0.00000 -0.00000 0.00000" xyz="-0.20000 0.20000 0.00000"/>
		<axis xyz="1.00000 1.00000 0.00000"/>
	</joint>
	<joint name="jointfix_3_10" type="fixed">
		<parent link="link0_10"/>
		<child link="front_right_foot"/>
		<dynamics damping="1.0" friction="0.0001"/>
		<origin rpy="0.00000 -0.00000 0.00000" xyz="0.00000 0.00000 0.00000"/>
		<axis xyz="0.00000 0.00000 0.00000"/>
	</joint>
	<joint name="jointfix_8_0" type="fixed">
		<parent link="torso"/>
		<child link="left_back_leg"/>
		<dynamics damping="1.0" friction="0.0001"/>
		<origin rpy="0.00000 -0.00000 0.00000" xyz="0.00000 0.00000 0.00000"/>
		<axis xyz="0.00000 0.00000 0.00000"/>
	</joint>
	<joint name="hip_3" type="continuous">
		<parent link="left_back_leg"/>
		<child link="link0_13"/>
		<dynamics damping="1.0" friction="0.0001"/>
		<origin rpy="0.00000 -0.00000 0.00000" xyz="-0.20000 -0.20000 0.00000"/>
		<axis xyz="0.00000 0.00000 1.00000"/>
	</joint>
	<joint name="jointfix_7_13" type="fixed">
		<parent link="link0_13"/>
		<child link="aux_3"/>
		<dynamics damping="1.0" friction="0.0001"/>
		<origin rpy="0.00000 -0.00000 0.00000" xyz="0.00000 0.00000 0.00000"/>
		<axis xyz="0.00000 0.00000 0.00000"/>
	</joint>
	<joint name="ankle_3" type="continuous">
		<parent link="aux_3"/>
		<child link="link0_15"/>
		<dynamics damping="1.0" friction="0.0001"/>
		<origin rpy="0.00000 -0.00000 0.00000" xyz="-0.20000 -0.20000 0.00000"/>
		<axis xyz="-1.00000 1.00000 0.00000"/>
	</joint>
	<joint name="jointfix_6_15" type="fixed">
		<parent link="link0_15"/>
		<child link="left_back_foot"/>
		<dynamics damping="1.0" friction="0.0001"/>
		<origin rpy="0.00000 -0.00000 0.00000" xyz="0.00000 0.00000 0.00000"/>
		<axis xyz="0.00000 0.00000 0.00000"/>
	</joint>
	<joint name="jointfix_11_0" type="fixed">
		<parent link="torso"/>
		<child link="right_back_leg"/>
		<dynamics damping="1.0" friction="0.0001"/>
		<origin rpy="0.00000 -0.00000 0.00000" xyz="0.00000 0.00000 0.00000"/>
		<axis xyz="0.00000 0.00000 0.00000"/>
	</joint>
	<joint name="hip_4" type="continuous">
		<parent link="right_back_leg"/>
		<child link="link0_18"/>
		<dynamics damping="1.0" friction="0.0001"/>
		<origin rpy="0.00000 -0.00000 0.00000" xyz="0.20000 -0.20000 0.00000"/>
		<axis xyz="0.00000 0.00000 1.00000"/>
	</joint>
	<joint name="jointfix_10_18" type="fixed">
		<parent link="link0_18"/>
		<child link="aux_4"/>
		<dynamics damping="1.0" friction="0.0001"/>
		<origin rpy="0.00000 -0.00000 0.00000" xyz="0.00000 0.00000 0.00000"/>
		<axis xyz="0.00000 0.00000 0.00000"/>
	</joint>
	<joint name="ankle_4" type="continuous">
		<parent link="aux_4"/>
		<child link="link0_20"/>
		<dynamics damping="1.0" friction="0.0001"/>
		<origin rpy="0.00000 -0.00000 0.00000" xyz="0.20000 -0.20000 0.00000"/>
		<axis xyz="1.00000 1.00000 0.00000"/>
	</joint>
	<joint name="jointfix_9_20" type="fixed">
		<parent link="link0_20"/>
		<child link="right_back_foot"/>
		<dynamics damping="1.0" friction="0.0001"/>
		<origin rpy="0.00000 -0.00000 0.00000" xyz="0.00000 0.00000 0.00000"/>
		<axis xyz="0.00000 0.00000 0.00000"/>
	</joint>
</robot>
