<?xml version="0.0" ?>
<robot name="">
	<link name="sphere_link">
		<inertial>
			<origin rpy="0.00000 -0.00000 0.00000" xyz="0.00000 0.00000 0.00000"/>
			<mass value="0.10000"/>
			<inertia ixx="0.00032" ixy="0" ixz="0" iyy="0.00032" iyz="0" izz="0.00032"/>
		</inertial>
		<visual>
			<origin rpy="0.00000 -0.00000 0.00000" xyz="0.00000 0.00000 0.00000"/>
			<geometry>
				<mesh filename="./textured_sphere_smooth.obj" scale="0.09000 0.09000 0.09000"/>
			</geometry>
			<material name="mat_-1_0">
				<color rgba="1.00000 1.00000 1.00000 1.00000" />
			</material>
		</visual>
		<collision>
			<origin rpy="0.00000 -0.00000 0.00000" xyz="0.00000 0.00000 0.00000"/>
			<geometry>
				<sphere radius="0.09000"/>
			</geometry>
		</collision>
	</link>
	<link name="leg3">
		<inertial>
			<origin rpy="0.00000 -0.00000 0.00000" xyz="0.00000 0.00000 -0.04000"/>
			<mass value="0.10000"/>
			<inertia ixx="0.00018" ixy="0" ixz="0" iyy="0.00018" iyz="0" izz="0.00003"/>
		</inertial>
		<visual>
			<origin rpy="0.00000 -0.00000 0.00000" xyz="0.00000 0.00000 -0.04000"/>
			<geometry>
				<capsule length="0.10000" radius="0.02000"/>
			</geometry>
			<material name="mat_-1_0">
				<color rgba="0.23438 0.72656 0.32812 1.00000" />
			</material>
		</visual>
		<collision>
			<origin rpy="0.00000 -0.00000 0.00000" xyz="0.00000 0.00000 -0.04000"/>
			<geometry>
				<capsule length="0.10000" radius="0.02000"/>
			</geometry>
		</collision>
	</link>
	<link name="leg3">
		<inertial>
			<origin rpy="0.00000 -0.00000 0.00000" xyz="0.00000 0.00000 -0.04000"/>
			<mass value="0.10000"/>
			<inertia ixx="0.00018" ixy="0" ixz="0" iyy="0.00018" iyz="0" izz="0.00003"/>
		</inertial>
		<visual>
			<origin rpy="0.00000 -0.00000 0.00000" xyz="0.00000 0.00000 -0.04000"/>
			<geometry>
				<capsule length="0.10000" radius="0.02000"/>
			</geometry>
			<material name="mat_-1_0">
				<color rgba="0.23438 0.72656 0.32812 1.00000" />
			</material>
		</visual>
		<collision>
			<origin rpy="0.00000 -0.00000 0.00000" xyz="0.00000 0.00000 -0.04000"/>
			<geometry>
				<capsule length="0.10000" radius="0.02000"/>
			</geometry>
		</collision>
	</link>
	<link name="leg3">
		<inertial>
			<origin rpy="0.00000 -0.00000 0.00000" xyz="0.00000 0.00000 -0.04000"/>
			<mass value="0.10000"/>
			<inertia ixx="0.00018" ixy="0" ixz="0" iyy="0.00018" iyz="0" izz="0.00003"/>
		</inertial>
		<visual>
			<origin rpy="0.00000 -0.00000 0.00000" xyz="0.00000 0.00000 -0.04000"/>
			<geometry>
				<capsule length="0.10000" radius="0.02000"/>
			</geometry>
			<material name="mat_-1_0">
				<color rgba="0.23438 0.72656 0.32812 1.00000" />
			</material>
		</visual>
		<collision>
			<origin rpy="0.00000 -0.00000 0.00000" xyz="0.00000 0.00000 -0.04000"/>
			<geometry>
				<capsule length="0.10000" radius="0.02000"/>
			</geometry>
		</collision>
	</link>
	<link name="leg3">
		<inertial>
			<origin rpy="0.00000 -0.00000 0.00000" xyz="0.00000 0.00000 -0.04000"/>
			<mass value="0.10000"/>
			<inertia ixx="0.00018" ixy="0" ixz="0" iyy="0.00018" iyz="0" izz="0.00003"/>
		</inertial>
		<visual>
			<origin rpy="0.00000 -0.00000 0.00000" xyz="0.00000 0.00000 -0.04000"/>
			<geometry>
				<capsule length="0.10000" radius="0.02000"/>
			</geometry>
			<material name="mat_-1_0">
				<color rgba="0.23438 0.72656 0.32812 1.00000" />
			</material>
		</visual>
		<collision>
			<origin rpy="0.00000 -0.00000 0.00000" xyz="0.00000 0.00000 -0.04000"/>
			<geometry>
				<capsule length="0.10000" radius="0.02000"/>
			</geometry>
		</collision>
	</link>
	<joint name="joint_dummy1" type="continuous">
		<parent link="sphere_link"/>
		<child link="leg0"/>
		<dynamics damping="1.0" friction="0.0001"/>
		<origin rpy="0.00000 0.00000 0.00000" xyz="0.08000 0.08000 -0.05000"/>
		<axis xyz="1.00000 0.00000 0.00000"/>
	</joint>
	<joint name="joint_dummy1" type="continuous">
		<parent link="sphere_link"/>
		<child link="leg1"/>
		<dynamics damping="1.0" friction="0.0001"/>
		<origin rpy="0.00000 0.00000 0.00000" xyz="-0.08000 0.08000 -0.05000"/>
		<axis xyz="1.00000 0.00000 0.00000"/>
	</joint>
	<joint name="joint_dummy1" type="continuous">
		<parent link="sphere_link"/>
		<child link="leg2"/>
		<dynamics damping="1.0" friction="0.0001"/>
		<origin rpy="0.00000 0.00000 0.00000" xyz="-0.08000 -0.08000 -0.05000"/>
		<axis xyz="1.00000 0.00000 0.00000"/>
	</joint>
	<joint name="joint_dummy1" type="continuous">
		<parent link="sphere_link"/>
		<child link="leg3"/>
		<dynamics damping="1.0" friction="0.0001"/>
		<origin rpy="0.00000 0.00000 0.00000" xyz="0.08000 -0.08000 -0.05000"/>
		<axis xyz="1.00000 0.00000 0.00000"/>
	</joint>
</robot>
